Workbook
Name FIRE目标: FIRE测算!$B$21
Name FIRE年支出: FIRE测算!$B$14

Sheet 总览看板
A1: 家庭资产与 FIRE 管理看板
A2: 数据截至 2026-09-15 ｜ 金额单位：人民币元 ｜ 蓝色＝手工输入 ｜ 绿色＝跨表引用 ｜ 黑色＝公式计算
A4: 一、资产总览
A5: 资产类别 | B5: 金额(元) | C5: 占总资产
A6: 现金及存款 | B6: =资产明细!G8 | C6: =IFERROR(B6/$B$13,"")
A7: 股票及证券 | B7: =资产明细!G15 | C7: =IFERROR(B7/$B$13,"")
A8: 基金及理财 | B8: =资产明细!G19 | C8: =IFERROR(B8/$B$13,"")
A9: 保险（储蓄型） | B9: =资产明细!G24 | C9: =IFERROR(B9/$B$13,"")
A10: 教育金专项（恒泰尊享） | B10: =资产明细!G27 | C10: =IFERROR(B10/$B$13,"")
A11: 自用房产（深圳城市山林） | B11: =资产明细!G29 | C11: =IFERROR(B11/$B$13,"")
A12: 投资性房地产（待售） | B12: =资产明细!G30+资产明细!G31+资产明细!G32 | C12: =IFERROR(B12/$B$13,"")
A13: 资产合计 | B13: =SUM(B6:B12) | C13: =1
A14: 负债合计 | B14: =资产明细!G40
A15: 净资产 | B15: =B13-B14
A16: 其中：可投资资产（不含保险） | B16: =资产明细!G44
A17: 其中：可立即变现资产（估算） | B17: =资产明细!G45
A18: 保险立即退保损失 | B18: =资产明细!G47
A19: 二、FIRE 财务自由进度
A20: 指标
A21: 年支出（元） | B21: =FIRE测算!B14 | C21: 取自「FIRE测算」
A22: 安全提款率 SWR | B22: =FIRE测算!B6 | C22: 默认 4%
A23: FIRE 目标资产（元） | B23: =FIRE测算!B21 | C23: ＝年支出 ÷ SWR
A24: 当前可投资资产（元） | B24: =FIRE测算!B26 | C24: 现金＋股票＋基金（年金按开关）
A25: 财务自由度（被动收入覆盖率） | B25: =FIRE测算!B29 | C25: 被动收入 ÷ 年支出
A26: FIRE 缺口（元） | B26: =FIRE测算!B30
A27: 预计达成所需年数 | B27: =FIRE测算!B43
A28: 预计达成日期 | B28: =FIRE测算!B44
A29: 预计退休年龄 | B29: =FIRE测算!B46
A30: FIRE 状态 | B30: =FIRE测算!B31
A32: 三、投资收益概览
A33: 指标
A34: 总投入成本／本金（元） | B34: =资产明细!H35 | C34: 已填写成本的项目合计
A35: 当前总市值（元） | B35: =资产明细!G35 | C35: 含全部持仓
A36: 累计盈亏（元） | B36: =资产明细!I35 | C36: 仅统计已填写成本的项目；阿里持仓成本待补充
A37: 累计收益率 | B37: =资产明细!J35 | C37: ＝累计盈亏 ÷ 已填成本
A39: 本表为自动计算看板，所有明细维护请在「资产明细」「收支流水」中进行。

Sheet 资产明细
A1: 家庭资产明细表
A2: 口径：人民币元；蓝色字体＝需手工维护的输入项；黑色＝公式自动计算；黄色底＝重点核对/需要补充
A4: 资产大类 | B4: 账户／产品 | C4: 持有数量／份额 | D4: 单价／单位金额 | E4: 币种 | F4: 汇率(→CNY) | G4: 市值(元) | H4: 成本／本金(元) | I4: 盈亏(元) | J4: 盈亏率 | K4: 占比 | L4: 流动性 | M4: 备注
A5: 现金及存款
A6: 现金及存款 | B6: 招商银行 | C6: 1 | D6: 1310000 | E6: CNY | F6: 1 | G6: =C6*D6*F6 | H6: 1310000 | I6: =IF(H6="","",G6-H6) | J6: =IFERROR(I6/H6,"") | K6: =IFERROR(G6/$G$35,"") | L6: 高 | M6: 活期＋存款，按最新余额更新
A7: 现金及存款 | B7: 工商银行 | C7: 1 | D7: 243000 | E7: CNY | F7: 1 | G7: =C7*D7*F7 | H7: 243000 | I7: =IF(H7="","",G7-H7) | J7: =IFERROR(I7/H7,"") | K7: =IFERROR(G7/$G$35,"") | L7: 高 | M7: 活期＋存款，按最新余额更新
A8: 现金及存款 小计 | G8: =SUM(G6:G7) | H8: =SUM(H6:H7) | I8: =SUM(I6:I7) | J8: =IFERROR(I8/H8,"") | K8: =IFERROR(G8/$G$35,"")
A9: 股票及证券
A10: 股票及证券 | B10: 阿里巴巴-W（09988.HK） | C10: 4004 | D10: 107.2 | E10: HKD | F10: 0.92 | G10: =C10*D10*F10 | I10: =IF(H10="","",G10-H10) | J10: =IFERROR(I10/H10,"") | K10: =IFERROR(G10/$G$35,"") | L10: 高 | M10: H股 4,004 股（3164＋840）；不含港股通 6,400 股（见下行，含在中信证券账户内）；单价请按最新股价更新
A11: 股票及证券 | B11: 阿里巴巴（BABA.US） | C11: 2177 | D11: 109.51 | E11: USD | F11: 7.15 | G11: =C11*D11*F11 | I11: =IF(H11="","",G11-H11) | J11: =IFERROR(I11/H11,"") | K11: =IFERROR(G11/$G$35,"") | L11: 高 | M11: 美股 ADR 2,177 股；单价请按最新股价更新
A12: 股票及证券 | B12: 阿里巴巴-W（港股通·中信证券账户内） | C12: 6400 | D12: 107.2 | E12: HKD | F12: 0.92 | G12: =C12*D12*F12 | H12: 865536 | I12: =IF(H12="","",G12-H12) | J12: =IFERROR(I12/H12,"") | K12: =IFERROR(G12/$G$35,"") | L12: 高 | M12: 自购，成本 147 HKD；含在中信证券账户 322 万市值内，本行单列、该账户按净额计，不重复
A13: 股票及证券 | B13: 九毛九（09922.HK·中信证券账户内） | C13: 63000 | D13: 1.035 | E13: HKD | F13: 0.92 | G13: =C13*D13*F13 | H13: 676972.8 | I13: =IF(H13="","",G13-H13) | J13: =IFERROR(I13/H13,"") | K13: =IFERROR(G13/$G$35,"") | L13: 中 | M13: 成本 11.68 HKD，浮亏约 -91%；含在中信证券账户内；建议分批清仓
A14: 股票及证券 | B14: 中信证券账户-其他持仓（净额） | C14: 1 | D14: 2528817.8 | E14: CNY | F14: 1 | G14: =C14*D14*F14 | H14: 2261491.2 | I14: =IF(H14="","",G14-H14) | J14: =IFERROR(I14/H14,"") | K14: =IFERROR(G14/$G$35,"") | L14: 高 | M14: ＝原账户市值 322 万 − 阿里港股通 63.1 万 − 九毛九 6.0 万（倒挤，请核对流水）；成本＝推算 380.4 万 − 两项成本
A15: 股票及证券 小计 | G15: =SUM(G10:G14) | H15: =SUM(H10:H14) | I15: =SUM(I10:I14) | J15: =IFERROR(I15/H15,"") | K15: =IFERROR(G15/$G$35,"")
A16: 基金及理财
A17: 基金及理财 | B17: 高毅晓峰基金（私募） | C17: 1 | D17: 1510000 | E17: CNY | F17: 1 | G17: =C17*D17*F17 | H17: 1000000 | I17: =IF(H17="","",G17-H17) | J17: =IFERROR(I17/H17,"") | K17: =IFERROR(G17/$G$35,"") | L17: 中 | M17: 2021-06 买入，本金100万
A18: 基金及理财 | B18: 泰康赢家人生（投连险） | C18: 1 | D18: 844000 | E18: CNY | F18: 1 | G18: =C18*D18*F18 | H18: 800000 | I18: =IF(H18="","",G18-H18) | J18: =IFERROR(I18/H18,"") | K18: =IFERROR(G18/$G$35,"") | L18: 中 | M18: 2020-12 买入，本金80万
A19: 基金及理财 小计 | G19: =SUM(G17:G18) | H19: =SUM(H17:H18) | I19: =SUM(I17:I18) | J19: =IFERROR(I19/H19,"") | K19: =IFERROR(G19/$G$35,"")
A20: 保险(储蓄型)
A21: 保险(储蓄型) | B21: 中意一生中意（尊享版）终身寿险 | C21: 1 | D21: 35603.36 | E21: CNY | F21: 1 | G21: =C21*D21*F21 | H21: 40000 | I21: =IF(H21="","",G21-H21) | J21: =IFERROR(I21/H21,"") | K21: =IFERROR(G21/$G$35,"") | L21: 低 | M21: 被保人=杜岩松；2024-10投保；现价为保单年度末值。⚠️受益人为「法定受益人」，建议改为指定受益人
A22: 保险(储蓄型) | B22: 泰康乐享百岁养老年金保险 | C22: 1 | D22: 1862535 | E22: CNY | F22: 1 | G22: =C22*D22*F22 | H22: 3012480 | I22: =IF(H22="","",G22-H22) | J22: =IFERROR(I22/H22,"") | K22: =IFERROR(G22/$G$35,"") | L22: 低 | M22: 被保人=杜岩松；60岁起月领1.5万／年领177,990元，保证给付25年；60岁后身故金为0；现价自60岁起递减至84岁归零
A23: 保险(储蓄型) | B23: 陆家嘴国泰金管家2.0（万能型） | C23: 1 | D23: 1000 | E23: CNY | F23: 1 | G23: =C23*D23*F23 | H23: 1000 | I23: =IF(H23="","",G23-H23) | J23: =IFERROR(I23/H23,"") | K23: =IFERROR(G23/$G$35,"") | L23: 低 | M23: 被保人=杜汐姮；趸交1000元；最低保证利率2%。★若另有「泰康乐赢1号」万能账户请在此行补充金额
A24: 保险(储蓄型) 小计 | G24: =SUM(G21:G23) | H24: =SUM(H21:H23) | I24: =SUM(I21:I23) | J24: =IFERROR(I24/H24,"") | K24: =IFERROR(G24/$G$35,"")
A25: 保险(教育金专项)
A26: 保险(教育金专项) | B26: 陆家嘴国泰恒泰尊享3.0版 | C26: 1 | D26: 1600567.3 | E26: CNY | F26: 1 | G26: =C26*D26*F26 | H26: 2000000 | I26: =IF(H26="","",G26-H26) | J26: =IFERROR(I26/H26,"") | K26: =IFERROR(G26/$G$35,"") | L26: 低 | M26: ★教育金专项：用于女儿18-22岁大学四年；被保人=杜汐姮／投保人(现价归属人)=杜岩松；每年减保≤保单年度初基本保额的20%(条款11.2)；有效保额3%/年递增
A27: 保险(教育金专项) 小计 | G27: =SUM(G26:G26) | H27: =SUM(H26:H26) | I27: =SUM(I26:I26) | J27: =IFERROR(I27/H27,"") | K27: =IFERROR(G27/$G$35,"")
A28: 房产（自用＋投资性房地产）
A29: 房产(自用) | B29: 深圳城市山林（自住） | C29: 1 | D29: 10000000 | E29: CNY | F29: 1 | G29: =C29*D29*F29 | I29: =IF(H29="","",G29-H29) | J29: =IFERROR(I29/H29,"") | K29: =IFERROR(G29/$G$35,"") | L29: 极低（自用） | M29: 自用住宅，不出售；估值约1,000万；抵押贷款余额200万见下方负债区
A30: 投资性房地产(待售) | B30: 深圳龙岗区恒大城市之光 | C30: 1 | D30: 1800000 | E30: CNY | F30: 1 | G30: =C30*D30*F30 | I30: =IF(H30="","",G30-H30) | J30: =IFERROR(I30/H30,"") | K30: =IFERROR(G30/$G$35,"") | L30: 中低（待售） | M30: ★投资性房地产（深圳龙岗·恒大城市之光），计划尽快出售；变现后转入可投资资产
A31: 投资性房地产(待售) | B31: 廊坊固安泊心园 | C31: 1 | D31: 850000 | E31: CNY | F31: 1 | G31: =C31*D31*F31 | I31: =IF(H31="","",G31-H31) | J31: =IFERROR(I31/H31,"") | K31: =IFERROR(G31/$G$35,"") | L31: 中低（待售） | M31: ★投资性房地产（廊坊固安·泊心园），计划尽快出售；变现后转入可投资资产
A32: 投资性房地产(待售) | B32: 廊坊空港孔雀城领航城 | C32: 1 | D32: 500000 | E32: CNY | F32: 1 | G32: =C32*D32*F32 | I32: =IF(H32="","",G32-H32) | J32: =IFERROR(I32/H32,"") | K32: =IFERROR(G32/$G$35,"") | L32: 中低（待售） | M32: ★投资性房地产（廊坊空港·孔雀城领航城），计划尽快出售；变现后转入可投资资产
A33: 房产合计 | G33: =SUM(G29:G32) | H33: =SUM(H29:H32) | I33: =SUM(I29:I32) | J33: =IFERROR(I33/H33,"") | K33: =IFERROR(G33/$G$35,"") | M33: 自用 1,000 万 ＋ 投资性房地产（待售）315 万＝1,315 万；投资房计划尽快出售，变现后并入可投资资产
A35: 资产合计 | G35: =G8+G15+G19+G24+G27+G33 | H35: =H8+H15+H19+H24+H27+H33 | I35: =I8+I15+I19+I24+I27+I33 | J35: =IFERROR(I35/H35,"") | K35: =1 | M35: 占总资产100%；盈亏仅含已填写成本的项目（阿里持仓成本待补充）
A37: 负债
A38: 负债 | B38: 住房贷款余额 | C38: 1 | D38: 2000000 | E38: CNY | F38: 1 | G38: =C38*D38*F38 | M38: 深圳城市山林（自住）抵押贷款余额约200万，请按实际剩余额度更新
A39: 负债 | B39: 其他负债 | C39: 1 | D39: 0 | E39: CNY | F39: 1 | G39: =C39*D39*F39 | M39: 如有负债请填写余额（正数）
A40: 负债合计 | G40: =SUM(G38:G39)
A41: 净资产 | G41: =G35-G40 | M41: ＝资产合计－负债合计
A43: 辅助指标（口径提示，供 FIRE 测算与看板引用）
A44: 可投资资产（不含任何保险） | G44: =G8+G15+G19 | H44: 现金＋股票＋基金，是 FIRE 的核心口径
...

Sheet 保险权益与现金流
A1: 人寿保险权益与现金流分析表
A2: 数据来源：明亚保险经纪《杜岩松家庭保障分析报告》2026-09-13 ＋ 三份保险条款 ｜ 金额单位：人民币元 ｜ 蓝色＝手工输入
A4: 一、保单台账（4 张保单）
A5: 序号 | B5: 被保人 | C5: 投保人／现价归属人 | D5: 保险公司 | E5: 产品名称 | F5: 险种 | G5: 保单号 | H5: 生效日 | I5: 基本保额 | J5: 累计已交保费 | K5: 当前现金价值 | L5: 身故受益人 | M5: 保值/领取要点 | N5: 关键条款与风险提示
A6: 1 | B6: 杜岩松 | C6: 杜岩松 | D6: 中意人寿 | E6: 中意一生中意（尊享版）终身寿险 | F6: 增额终身寿(分红) | G6: 88123297 | H6: 2024-10-31 | I6: 33240 | J6: 40000 | K6: 35603.36 | L6: ⚠️法定受益人 | M6: 有效保额 2%/年 递增 | N6: ① 受益人为「法定受益人」，建议改为【指定受益人】，避免理赔纠纷与债务隐患；② 分红不保证；③ 含年金转换权；④ 保证现价 CAGR 仅约 1.9%
A7: 2 | B7: 杜岩松 | C7: 杜岩松 | D7: 泰康人寿 | E7: 泰康乐享百岁养老年金保险（分红型） | F7: 养老年金 | G7: 19162486 | H7: 2023-12-14 | I7: 15000 | J7: 3012480 | K7: 1862535 | L7: 杜汐姮 100% | M7: 60岁起月领 15,000 元 | N7: ① 年领＝基本保额×11.866＝177,990 元/年；② 保证给付期 25 个保单年度（60→84岁），期内身故一次性补付未领余额（不计息）；③ ★60岁（首个领取日）之后身故，身故保险金＝0；④ 现价自 60 岁起递减，84 岁归零；⑤ 保单贷款上限＝现价×80%，单次≤180天；⑥ 生存金受益人默认投保人本人
A8: 3 | B8: 杜汐姮 | C8: 杜岩松 | D8: 陆家嘴国泰人寿 | E8: 陆家嘴国泰恒泰尊享（3.0版）终身寿险 | F8: 增额终身寿 | G8: G11000462820 | H8: 2023-12-27 | I8: 1916479.8 | J8: 2000000 | K8: 1600567.3 | L8: 杜岩松 100% | M8: 有效保额 3%/年 递增 | N8: ★【教育金专项】用于女儿 18-22 岁大学四年。① 条款 11.2：每年累计减少的基本保险金额之和不得超过申请时所在保单年度初基本保险金额的 20% ← 取现能力硬约束；② 身故比例 18-40岁160%／41-60岁140%／61岁+120%；③ 含水陆客运交通意外身故金（基本保额×50%，18岁后前20个保单年度且70岁前）；④ 第二投保人权益（§9）★建议现在设置，否则投保人身故时现价按遗产处理；⑤ 借款上限＝现价×80%，单次≤6个月；⑥ 满60周岁且生效满10周年可转换为年金
A9: 4 | B9: 杜汐姮 | C9: 杜岩松 | D9: 陆家嘴国泰人寿 | E9: 陆家嘴国泰金管家2.0终身寿险（万能型） | F9: 万能险 | G9: G11000462835 | H9: 2023-12-27 | I9: 0 | J9: 1000 | K9: 1000 | L9: 杜岩松 100% | M9: 最低保证利率 2% | N9: ① 趸交 1,000 元，金额极小，主要作为账户载体；② 等待期 180 天；③ ★若家庭另持「泰康乐赢1号终身寿险（万能型）」，请在「资产明细」单列一行，不要与之合并
J10: =SUM(J6:J9) | K10: =SUM(K6:K9) | N10: ="累计已交保费 "&TEXT(J10,"#,##0")&" 元 ｜ 当前现金价值 "&TEXT(K10,"#,##0")&" 元 ｜ 立即退保损失 "&TEXT(K10-J10,"#,##0")&" 元（"&TEXT(IFERROR((K10-J10)/J10,0),"0.0%")&"）"
A12: 二、现金价值与年金现金流（按年龄，现价为保单年度末值）
A13: 年龄 | B13: 年份 | C13: 中意·现价 | D13: 泰康·现价 | E13: 恒泰尊享·现价 | F13: 现价合计 | G13: 泰康年金年领取 | H13: 泰康年金累计领取 | I13: 年金+现价 | J13: 备注
A14: 46 | B14: 2026 | C14: 35603.36 | D14: 1862535 | E14: 1600567.3 | F14: =SUM(C14:E14) | G14: 0 | H14: =G14 | I14: =F14+H14 | J14: 2026-09 基准；保险现价合计 349.97 万（对账用）
A15: 47 | B15: 2027 | C15: 36790.03 | D15: 1935345 | E15: 1808122 | F15: =SUM(C15:E15) | G15: 0 | H15: =H14+G15 | I15: =F15+H15
A16: 48 | B16: 2028 | C16: 38016.59 | D16: 2011020 | E16: 2026715.7 | F16: =SUM(C16:E16) | G16: 0 | H16: =H15+G16 | I16: =F16+H16 | J16: 女儿 18 岁入学
A17: 49 | B17: 2029 | C17: 39283.03 | D17: 2089695 | E17: 2256635.8 | F17: =SUM(C17:E17) | G17: 0 | H17: =H16+G17 | I17: =F17+H17
A18: 50 | B18: 2030 | C18: 40596.01 | D18: 2171505 | E18: 2324210.9 | F18: =SUM(C18:E18) | G18: 0 | H18: =H17+G18 | I18: =F18+H18
A19: 51 | B19: 2031 | C19: 41343.91 | D19: 2256615 | E19: 2393798.3 | F19: =SUM(C19:E19) | G19: 0 | H19: =H18+G19 | I19: =F19+H19 | J19: 女儿 21 岁，大学最后一年
A20: 52 | B20: 2032 | C20: 42101.78 | D20: 2345175 | E20: 2465493.8 | F20: =SUM(C20:E20) | G20: 0 | H20: =H19+G20 | I20: =F20+H20
A21: 53 | B21: 2033 | C21: 42876.28 | D21: 2437365 | E21: 2539335.8 | F21: =SUM(C21:E21) | G21: 0 | H21: =H20+G21 | I21: =F21+H21
A22: 54 | B22: 2034 | C22: 43660.74 | D22: 2533380 | E22: 2615400.8 | F22: =SUM(C22:E22) | G22: 0 | H22: =H21+G22 | I22: =F22+H22
A23: 55 | B23: 2035 | C23: 44465.15 | D23: 2633400 | E23: 2693765.7 | F23: =SUM(C23:E23) | G23: 0 | H23: =H22+G23 | I23: =F23+H23
A24: 56 | B24: 2036 | C24: 45282.85 | D24: 2737665 | E24: 2774468.7 | F24: =SUM(C24:E24) | G24: 0 | H24: =H23+G24 | I24: =F24+H24
A25: 57 | B25: 2037 | C25: 46117.18 | D25: 2846385 | E25: 2857624.7 | F25: =SUM(C25:E25) | G25: 0 | H25: =H24+G25 | I25: =F25+H25
A26: 58 | B26: 2038 | C26: 46968.12 | D26: 2959815 | E26: 2943272.2 | F26: =SUM(C26:E26) | G26: 0 | H26: =H25+G26 | I26: =F26+H26
A27: 59 | B27: 2039 | C27: 47839.01 | D27: 3077970 | E27: 3031506.9 | F27: =SUM(C27:E27) | G27: 0 | H27: =H26+G27 | I27: =F27+H27 | J27: 退休前最后一年；泰康现价达峰 307.8 万
A28: 60 | B28: 2040 | C28: 48729.84 | D28: 2796660 | E28: 3122386.4 | F28: =SUM(C28:E28) | G28: 177990 | H28: =H27+G28 | I28: =F28+H28 | J28: ★年金开始领取；泰康现价断崖下降
A29: 61 | B29: 2041 | C29: 49760.03 | D29: 2605695 | E29: 3214104 | F29: =SUM(C29:E29) | G29: 177990 | H29: =H28+G29 | I29: =F29+H29
A30: 62 | B30: 2042 | C30: 50790.5 | D30: 2415000 | E30: 3308970.8 | F30: =SUM(C30:E30) | G30: 177990 | H30: =H29+G30 | I30: =F30+H30
A31: 63 | B31: 2043 | C31: 51821.26 | D31: 2223000 | E31: 3407025 | F31: =SUM(C31:E31) | G31: 177990 | H31: =H30+G31 | I31: =F31+H31
A32: 64 | B32: 2044 | C32: 52852.3 | D32: 2029500 | E32: 3508350 | F32: =SUM(C32:E32) | G32: 177990 | H32: =H31+G32 | I32: =F32+H32
A33: 65 | B33: 2045 | C33: 53883.63 | D33: 1833000 | E33: 3613032.6 | F33: =SUM(C33:E33) | G33: 177990 | H33: =H32+G33 | I33: =F33+H33
A35: 三、保障缺口分析（来源：明亚《杜岩松家庭保障分析报告》2026-09-13）
A36: 成员 | B36: 保障类型 | C36: 已有保障(元) | D36: 建议保障(元) | E36: 缺口(元) | F36: 优先级 | G36: 说明
A37: 杜岩松（46岁） | B37: 重大疾病 | C37: 0 | D37: 780000 | E37: =MAX(D37-C37,0) | F37: P0 | G37: 重疾保额严重缺失，一旦发生将直接侵蚀 FIRE 资产
A38: 杜岩松（46岁） | B38: 医疗保险 | C38: 0 | D38: 1000000 | E38: =MAX(D38-C38,0) | F38: P1 | G38: 无任何商业医疗，大额医疗费用需完全自付
A39: 杜岩松（46岁） | B39: 寿险(身故) | C39: 33240 | D39: 3360000 | E39: =MAX(D39-C39,0) | F39: P0 | G39: 缺口 332.68 万；身故情景下 FIRE 进度将由约 135% 降至约 91%
A40: 杜岩松（46岁） | B40: 意外险 | C40: 0 | D40: 850000 | E40: =MAX(D40-C40,0) | F40: P1 | G40: 无意外保障
A41: 杜岩松（46岁） | B41: 养老年金 | C41: 177990 | D41: 260000 | E41: =MAX(D41-C41,0) | F41: P1 | G41: 已有年金 17.8 万/年，距建议 26 万/年缺 8.2 万/年（元/年口径）
A42: 杜汐姮（16岁） | B42: 重大疾病 | C42: 0 | D42: 530000 | E42: =MAX(D42-C42,0) | F42: P1 | G42: 未成年人重疾保障缺失
A43: 杜汐姮（16岁） | B43: 医疗保险 | C43: 0 | D43: 1000000 | E43: =MAX(D43-C43,0) | F43: P1 | G43: 无商业医疗
...

Sheet 教育金规划
A1: 教育金专项规划（陆家嘴国泰恒泰尊享 3.0）
A2: 用途：保障女儿 Elysia 大学四年费用 ｜ 硬约束：条款 11.2 每年减保 ≤ 保单年度初基本保额的 20% ｜ 蓝色＝手工输入
A4: 一、规划参数
A5: 女儿当前年龄 | D5: 16 | E5: 手工输入
A6: 预计入学年龄 | D6: 18 | E6: 手工输入
A7: 大学年数（取现年数） | D7: 4 | E7: 手工输入
A8: 每年需求金额（元） | D8: 600000 | E8: ★请按实际规划填写（国内约 3–8 万/年；海外约 30–60 万/年）
A9: 保单基本保险金额（元） | D9: 1916479.8 | E9: 取自保单：1,916,479.81 元
A10: 当前现金价值（元） | D10: 1600567.3 | E10: 2026-12 保单年度末值
A11: 每年减保上限（比例） | D11: 0.2 | E11: 条款 11.2：不得超过当年度初基本保险金额的 20%
A12: 入学年份 | D12: 2028 | E12: ＝2026 ＋ 入学年龄 − 当前年龄
A14: 二、逐年取现推演（在 20%/年 减保上限下，计算每年可提取金额）
A15: 年龄 | B15: 年份 | C15: 当年需求(元) | D15: 不减保时现价(元) | E15: 当年可取现(元) | F15: 累计取现(元) | G15: 减保后剩余保额比例 | H15: 当年末剩余现价(元) | I15: 满足度 | J15: 提示
A16: =$D$6 | B16: =$D$12 | C16: =IF(A16>=$D$6+$D$7,0,$D$8) | D16: =IFERROR(INDEX(保险权益与现金流!$E$14:$E$33,MATCH(B16,保险权益与现金流!$B$14:$B$33,0)),"") | E16: =IF(C16=0,0,MIN(C16,$D$11*(1)*D16)) | F16: =E16 | G16: =IF(D16=0,1,1-E16/D16) | H16: =IFERROR(G16*D16,"") | I16: =IF(C16=0,"—",IF(E16>=C16,"充足","不足")) | J16: =IF(C16=0,"",IF(E16<C16,"★当年受 20% 减保上限约束，缺口 "&TEXT(C16-E16,"#,##0")&" 元；建议提前 1–2 年开始减保或延长取现年份",""))
A17: =A16+1 | B17: =B16+1 | C17: =IF(A17>=$D$6+$D$7,0,$D$8) | D17: =IFERROR(INDEX(保险权益与现金流!$E$14:$E$33,MATCH(B17,保险权益与现金流!$B$14:$B$33,0)),"") | E17: =IF(C17=0,0,MIN(C17,$D$11*(G16)*D17)) | F17: =F16+E17 | G17: =IF(D17=0,0,G16*(1-E17/D17)) | H17: =IFERROR(G17*D17,"") | I17: =IF(C17=0,"—",IF(E17>=C17,"充足","不足")) | J17: =IF(C17=0,"",IF(E17<C17,"★当年受 20% 减保上限约束，缺口 "&TEXT(C17-E17,"#,##0")&" 元；建议提前 1–2 年开始减保或延长取现年份",""))
A18: =A17+1 | B18: =B17+1 | C18: =IF(A18>=$D$6+$D$7,0,$D$8) | D18: =IFERROR(INDEX(保险权益与现金流!$E$14:$E$33,MATCH(B18,保险权益与现金流!$B$14:$B$33,0)),"") | E18: =IF(C18=0,0,MIN(C18,$D$11*(G17)*D18)) | F18: =F17+E18 | G18: =IF(D18=0,0,G17*(1-E18/D18)) | H18: =IFERROR(G18*D18,"") | I18: =IF(C18=0,"—",IF(E18>=C18,"充足","不足")) | J18: =IF(C18=0,"",IF(E18<C18,"★当年受 20% 减保上限约束，缺口 "&TEXT(C18-E18,"#,##0")&" 元；建议提前 1–2 年开始减保或延长取现年份",""))
A19: =A18+1 | B19: =B18+1 | C19: =IF(A19>=$D$6+$D$7,0,$D$8) | D19: =IFERROR(INDEX(保险权益与现金流!$E$14:$E$33,MATCH(B19,保险权益与现金流!$B$14:$B$33,0)),"") | E19: =IF(C19=0,0,MIN(C19,$D$11*(G18)*D19)) | F19: =F18+E19 | G19: =IF(D19=0,0,G18*(1-E19/D19)) | H19: =IFERROR(G19*D19,"") | I19: =IF(C19=0,"—",IF(E19>=C19,"充足","不足")) | J19: =IF(C19=0,"",IF(E19<C19,"★当年受 20% 减保上限约束，缺口 "&TEXT(C19-E19,"#,##0")&" 元；建议提前 1–2 年开始减保或延长取现年份",""))
A20: =A19+1 | B20: =B19+1 | C20: =IF(A20>=$D$6+$D$7,0,$D$8) | D20: =IFERROR(INDEX(保险权益与现金流!$E$14:$E$33,MATCH(B20,保险权益与现金流!$B$14:$B$33,0)),"") | E20: =IF(C20=0,0,MIN(C20,$D$11*(G19)*D20)) | F20: =F19+E20 | G20: =IF(D20=0,0,G19*(1-E20/D20)) | H20: =IFERROR(G20*D20,"") | I20: =IF(C20=0,"—",IF(E20>=C20,"充足","不足")) | J20: =IF(C20=0,"",IF(E20<C20,"★当年受 20% 减保上限约束，缺口 "&TEXT(C20-E20,"#,##0")&" 元；建议提前 1–2 年开始减保或延长取现年份",""))
A21: =A20+1 | B21: =B20+1 | C21: =IF(A21>=$D$6+$D$7,0,$D$8) | D21: =IFERROR(INDEX(保险权益与现金流!$E$14:$E$33,MATCH(B21,保险权益与现金流!$B$14:$B$33,0)),"") | E21: =IF(C21=0,0,MIN(C21,$D$11*(G20)*D21)) | F21: =F20+E21 | G21: =IF(D21=0,0,G20*(1-E21/D21)) | H21: =IFERROR(G21*D21,"") | I21: =IF(C21=0,"—",IF(E21>=C21,"充足","不足")) | J21: =IF(C21=0,"",IF(E21<C21,"★当年受 20% 减保上限约束，缺口 "&TEXT(C21-E21,"#,##0")&" 元；建议提前 1–2 年开始减保或延长取现年份",""))
A23: 三、汇总与结论
A24: 大学期间总需求（元） | D24: =SUM(C16:C21)
A25: 保单可覆盖金额（元） | D25: =SUM(E16:E21)
A26: 资金缺口（＋）／盈余（－）（元） | D26: =D24-D25
A27: 覆盖率 | D27: =IFERROR(D25/D24,"")
A28: 四年后仍保留保额比例 | D28: =G21
A29: 四年后仍保留现价（元） | D29: =H21
A31: ① 现行「每年减保 ≤ 20% 基本保额」是可提取金额的硬约束：四年最多约 131 万元（按现行现价测算）。
A32: ② 若四年需求 ≤ 131 万元（约 32.7 万元/年以内），保单可全额覆盖，且四年后仍保留约 41% 保额与约 98 万元现价。
A33: ③ 若为海外留学（约 30–60 万元/年），四年需求 120–240 万元，将接近或超过上限——需提前 1–2 年（女儿 16–17 岁）就开始减保，或延长取现至第 5–6 年。
A34: ④ 备选工具：① 保单贷款（现价×80%，单次≤6 个月）；② 其他资产（现金 155 万、高毅晓峰 151 万）；③ 不建议对泰康年金减保，会直接削减退休现金流。
A35: ⑤ 本保单被保人是女儿、投保人（现价归属人）是杜岩松。★建议立即在条款 §9 设置「第二投保人」，否则投保人身故时现价将进入遗产处理，产生不必要的纠纷与费用。
A36: ⑥ 本表「当年可取现」已按条款上限计算；若实际需要超过上限，请在「提示」列查看缺口，并在参数区调整取现年数或年需求。

Sheet 收支记账
A1: 月度收支记账表
A2: 金额单位：人民币元；月度行自动汇总自「收支流水」；蓝色字体＝手工输入
A4: 一、月度收支汇总（自动汇总）
A5: 月份 | B5: 工资收入 | C5: 投资收益 | D5: 其他收入 | E5: 收入合计 | F5: 生活支出 | G5: 房贷/租金 | H5: 教育支出 | I5: 保险支出 | J5: 其他支出 | K5: 支出合计 | L5: 当月结余 | M5: 储蓄率 | N5: 累计结余
A6: 46266 | B6: =SUMIFS(收支流水!$E$4:$E$303,收支流水!$B$4:$B$303,"收入",收支流水!$C$4:$C$303,B$5,收支流水!$A$4:$A$303,">="&$A6,收支流水!$A$4:$A$303,"<"&EDATE($A6,1)) | C6: =SUMIFS(收支流水!$E$4:$E$303,收支流水!$B$4:$B$303,"收入",收支流水!$C$4:$C$303,C$5,收支流水!$A$4:$A$303,">="&$A6,收支流水!$A$4:$A$303,"<"&EDATE($A6,1)) | D6: =SUMIFS(收支流水!$E$4:$E$303,收支流水!$B$4:$B$303,"收入",收支流水!$C$4:$C$303,D$5,收支流水!$A$4:$A$303,">="&$A6,收支流水!$A$4:$A$303,"<"&EDATE($A6,1)) | E6: =SUM(B6:D6) | F6: =SUMIFS(收支流水!$E$4:$E$303,收支流水!$B$4:$B$303,"支出",收支流水!$C$4:$C$303,F$5,收支流水!$A$4:$A$303,">="&$A6,收支流水!$A$4:$A$303,"<"&EDATE($A6,1)) | G6: =SUMIFS(收支流水!$E$4:$E$303,收支流水!$B$4:$B$303,"支出",收支流水!$C$4:$C$303,G$5,收支流水!$A$4:$A$303,">="&$A6,收支流水!$A$4:$A$303,"<"&EDATE($A6,1)) | H6: =SUMIFS(收支流水!$E$4:$E$303,收支流水!$B$4:$B$303,"支出",收支流水!$C$4:$C$303,H$5,收支流水!$A$4:$A$303,">="&$A6,收支流水!$A$4:$A$303,"<"&EDATE($A6,1)) | I6: =SUMIFS(收支流水!$E$4:$E$303,收支流水!$B$4:$B$303,"支出",收支流水!$C$4:$C$303,I$5,收支流水!$A$4:$A$303,">="&$A6,收支流水!$A$4:$A$303,"<"&EDATE($A6,1)) | J6: =SUMIFS(收支流水!$E$4:$E$303,收支流水!$B$4:$B$303,"支出",收支流水!$C$4:$C$303,J$5,收支流水!$A$4:$A$303,">="&$A6,收支流水!$A$4:$A$303,"<"&EDATE($A6,1)) | K6: =SUM(F6:J6) | L6: =E6-K6 | M6: =IF(E6=0,"",L6/E6) | N6: =L6
A7: 46296 | B7: =SUMIFS(收支流水!$E$4:$E$303,收支流水!$B$4:$B$303,"收入",收支流水!$C$4:$C$303,B$5,收支流水!$A$4:$A$303,">="&$A7,收支流水!$A$4:$A$303,"<"&EDATE($A7,1)) | C7: =SUMIFS(收支流水!$E$4:$E$303,收支流水!$B$4:$B$303,"收入",收支流水!$C$4:$C$303,C$5,收支流水!$A$4:$A$303,">="&$A7,收支流水!$A$4:$A$303,"<"&EDATE($A7,1)) | D7: =SUMIFS(收支流水!$E$4:$E$303,收支流水!$B$4:$B$303,"收入",收支流水!$C$4:$C$303,D$5,收支流水!$A$4:$A$303,">="&$A7,收支流水!$A$4:$A$303,"<"&EDATE($A7,1)) | E7: =SUM(B7:D7) | F7: =SUMIFS(收支流水!$E$4:$E$303,收支流水!$B$4:$B$303,"支出",收支流水!$C$4:$C$303,F$5,收支流水!$A$4:$A$303,">="&$A7,收支流水!$A$4:$A$303,"<"&EDATE($A7,1)) | G7: =SUMIFS(收支流水!$E$4:$E$303,收支流水!$B$4:$B$303,"支出",收支流水!$C$4:$C$303,G$5,收支流水!$A$4:$A$303,">="&$A7,收支流水!$A$4:$A$303,"<"&EDATE($A7,1)) | H7: =SUMIFS(收支流水!$E$4:$E$303,收支流水!$B$4:$B$303,"支出",收支流水!$C$4:$C$303,H$5,收支流水!$A$4:$A$303,">="&$A7,收支流水!$A$4:$A$303,"<"&EDATE($A7,1)) | I7: =SUMIFS(收支流水!$E$4:$E$303,收支流水!$B$4:$B$303,"支出",收支流水!$C$4:$C$303,I$5,收支流水!$A$4:$A$303,">="&$A7,收支流水!$A$4:$A$303,"<"&EDATE($A7,1)) | J7: =SUMIFS(收支流水!$E$4:$E$303,收支流水!$B$4:$B$303,"支出",收支流水!$C$4:$C$303,J$5,收支流水!$A$4:$A$303,">="&$A7,收支流水!$A$4:$A$303,"<"&EDATE($A7,1)) | K7: =SUM(F7:J7) | L7: =E7-K7 | M7: =IF(E7=0,"",L7/E7) | N7: =N6+L7
A8: 46327 | B8: =SUMIFS(收支流水!$E$4:$E$303,收支流水!$B$4:$B$303,"收入",收支流水!$C$4:$C$303,B$5,收支流水!$A$4:$A$303,">="&$A8,收支流水!$A$4:$A$303,"<"&EDATE($A8,1)) | C8: =SUMIFS(收支流水!$E$4:$E$303,收支流水!$B$4:$B$303,"收入",收支流水!$C$4:$C$303,C$5,收支流水!$A$4:$A$303,">="&$A8,收支流水!$A$4:$A$303,"<"&EDATE($A8,1)) | D8: =SUMIFS(收支流水!$E$4:$E$303,收支流水!$B$4:$B$303,"收入",收支流水!$C$4:$C$303,D$5,收支流水!$A$4:$A$303,">="&$A8,收支流水!$A$4:$A$303,"<"&EDATE($A8,1)) | E8: =SUM(B8:D8) | F8: =SUMIFS(收支流水!$E$4:$E$303,收支流水!$B$4:$B$303,"支出",收支流水!$C$4:$C$303,F$5,收支流水!$A$4:$A$303,">="&$A8,收支流水!$A$4:$A$303,"<"&EDATE($A8,1)) | G8: =SUMIFS(收支流水!$E$4:$E$303,收支流水!$B$4:$B$303,"支出",收支流水!$C$4:$C$303,G$5,收支流水!$A$4:$A$303,">="&$A8,收支流水!$A$4:$A$303,"<"&EDATE($A8,1)) | H8: =SUMIFS(收支流水!$E$4:$E$303,收支流水!$B$4:$B$303,"支出",收支流水!$C$4:$C$303,H$5,收支流水!$A$4:$A$303,">="&$A8,收支流水!$A$4:$A$303,"<"&EDATE($A8,1)) | I8: =SUMIFS(收支流水!$E$4:$E$303,收支流水!$B$4:$B$303,"支出",收支流水!$C$4:$C$303,I$5,收支流水!$A$4:$A$303,">="&$A8,收支流水!$A$4:$A$303,"<"&EDATE($A8,1)) | J8: =SUMIFS(收支流水!$E$4:$E$303,收支流水!$B$4:$B$303,"支出",收支流水!$C$4:$C$303,J$5,收支流水!$A$4:$A$303,">="&$A8,收支流水!$A$4:$A$303,"<"&EDATE($A8,1)) | K8: =SUM(F8:J8) | L8: =E8-K8 | M8: =IF(E8=0,"",L8/E8) | N8: =N7+L8
A9: 46357 | B9: =SUMIFS(收支流水!$E$4:$E$303,收支流水!$B$4:$B$303,"收入",收支流水!$C$4:$C$303,B$5,收支流水!$A$4:$A$303,">="&$A9,收支流水!$A$4:$A$303,"<"&EDATE($A9,1)) | C9: =SUMIFS(收支流水!$E$4:$E$303,收支流水!$B$4:$B$303,"收入",收支流水!$C$4:$C$303,C$5,收支流水!$A$4:$A$303,">="&$A9,收支流水!$A$4:$A$303,"<"&EDATE($A9,1)) | D9: =SUMIFS(收支流水!$E$4:$E$303,收支流水!$B$4:$B$303,"收入",收支流水!$C$4:$C$303,D$5,收支流水!$A$4:$A$303,">="&$A9,收支流水!$A$4:$A$303,"<"&EDATE($A9,1)) | E9: =SUM(B9:D9) | F9: =SUMIFS(收支流水!$E$4:$E$303,收支流水!$B$4:$B$303,"支出",收支流水!$C$4:$C$303,F$5,收支流水!$A$4:$A$303,">="&$A9,收支流水!$A$4:$A$303,"<"&EDATE($A9,1)) | G9: =SUMIFS(收支流水!$E$4:$E$303,收支流水!$B$4:$B$303,"支出",收支流水!$C$4:$C$303,G$5,收支流水!$A$4:$A$303,">="&$A9,收支流水!$A$4:$A$303,"<"&EDATE($A9,1)) | H9: =SUMIFS(收支流水!$E$4:$E$303,收支流水!$B$4:$B$303,"支出",收支流水!$C$4:$C$303,H$5,收支流水!$A$4:$A$303,">="&$A9,收支流水!$A$4:$A$303,"<"&EDATE($A9,1)) | I9: =SUMIFS(收支流水!$E$4:$E$303,收支流水!$B$4:$B$303,"支出",收支流水!$C$4:$C$303,I$5,收支流水!$A$4:$A$303,">="&$A9,收支流水!$A$4:$A$303,"<"&EDATE($A9,1)) | J9: =SUMIFS(收支流水!$E$4:$E$303,收支流水!$B$4:$B$303,"支出",收支流水!$C$4:$C$303,J$5,收支流水!$A$4:$A$303,">="&$A9,收支流水!$A$4:$A$303,"<"&EDATE($A9,1)) | K9: =SUM(F9:J9) | L9: =E9-K9 | M9: =IF(E9=0,"",L9/E9) | N9: =N8+L9
A10: 46388 | B10: =SUMIFS(收支流水!$E$4:$E$303,收支流水!$B$4:$B$303,"收入",收支流水!$C$4:$C$303,B$5,收支流水!$A$4:$A$303,">="&$A10,收支流水!$A$4:$A$303,"<"&EDATE($A10,1)) | C10: =SUMIFS(收支流水!$E$4:$E$303,收支流水!$B$4:$B$303,"收入",收支流水!$C$4:$C$303,C$5,收支流水!$A$4:$A$303,">="&$A10,收支流水!$A$4:$A$303,"<"&EDATE($A10,1)) | D10: =SUMIFS(收支流水!$E$4:$E$303,收支流水!$B$4:$B$303,"收入",收支流水!$C$4:$C$303,D$5,收支流水!$A$4:$A$303,">="&$A10,收支流水!$A$4:$A$303,"<"&EDATE($A10,1)) | E10: =SUM(B10:D10) | F10: =SUMIFS(收支流水!$E$4:$E$303,收支流水!$B$4:$B$303,"支出",收支流水!$C$4:$C$303,F$5,收支流水!$A$4:$A$303,">="&$A10,收支流水!$A$4:$A$303,"<"&EDATE($A10,1)) | G10: =SUMIFS(收支流水!$E$4:$E$303,收支流水!$B$4:$B$303,"支出",收支流水!$C$4:$C$303,G$5,收支流水!$A$4:$A$303,">="&$A10,收支流水!$A$4:$A$303,"<"&EDATE($A10,1)) | H10: =SUMIFS(收支流水!$E$4:$E$303,收支流水!$B$4:$B$303,"支出",收支流水!$C$4:$C$303,H$5,收支流水!$A$4:$A$303,">="&$A10,收支流水!$A$4:$A$303,"<"&EDATE($A10,1)) | I10: =SUMIFS(收支流水!$E$4:$E$303,收支流水!$B$4:$B$303,"支出",收支流水!$C$4:$C$303,I$5,收支流水!$A$4:$A$303,">="&$A10,收支流水!$A$4:$A$303,"<"&EDATE($A10,1)) | J10: =SUMIFS(收支流水!$E$4:$E$303,收支流水!$B$4:$B$303,"支出",收支流水!$C$4:$C$303,J$5,收支流水!$A$4:$A$303,">="&$A10,收支流水!$A$4:$A$303,"<"&EDATE($A10,1)) | K10: =SUM(F10:J10) | L10: =E10-K10 | M10: =IF(E10=0,"",L10/E10) | N10: =N9+L10
A11: 46419 | B11: =SUMIFS(收支流水!$E$4:$E$303,收支流水!$B$4:$B$303,"收入",收支流水!$C$4:$C$303,B$5,收支流水!$A$4:$A$303,">="&$A11,收支流水!$A$4:$A$303,"<"&EDATE($A11,1)) | C11: =SUMIFS(收支流水!$E$4:$E$303,收支流水!$B$4:$B$303,"收入",收支流水!$C$4:$C$303,C$5,收支流水!$A$4:$A$303,">="&$A11,收支流水!$A$4:$A$303,"<"&EDATE($A11,1)) | D11: =SUMIFS(收支流水!$E$4:$E$303,收支流水!$B$4:$B$303,"收入",收支流水!$C$4:$C$303,D$5,收支流水!$A$4:$A$303,">="&$A11,收支流水!$A$4:$A$303,"<"&EDATE($A11,1)) | E11: =SUM(B11:D11) | F11: =SUMIFS(收支流水!$E$4:$E$303,收支流水!$B$4:$B$303,"支出",收支流水!$C$4:$C$303,F$5,收支流水!$A$4:$A$303,">="&$A11,收支流水!$A$4:$A$303,"<"&EDATE($A11,1)) | G11: =SUMIFS(收支流水!$E$4:$E$303,收支流水!$B$4:$B$303,"支出",收支流水!$C$4:$C$303,G$5,收支流水!$A$4:$A$303,">="&$A11,收支流水!$A$4:$A$303,"<"&EDATE($A11,1)) | H11: =SUMIFS(收支流水!$E$4:$E$303,收支流水!$B$4:$B$303,"支出",收支流水!$C$4:$C$303,H$5,收支流水!$A$4:$A$303,">="&$A11,收支流水!$A$4:$A$303,"<"&EDATE($A11,1)) | I11: =SUMIFS(收支流水!$E$4:$E$303,收支流水!$B$4:$B$303,"支出",收支流水!$C$4:$C$303,I$5,收支流水!$A$4:$A$303,">="&$A11,收支流水!$A$4:$A$303,"<"&EDATE($A11,1)) | J11: =SUMIFS(收支流水!$E$4:$E$303,收支流水!$B$4:$B$303,"支出",收支流水!$C$4:$C$303,J$5,收支流水!$A$4:$A$303,">="&$A11,收支流水!$A$4:$A$303,"<"&EDATE($A11,1)) | K11: =SUM(F11:J11) | L11: =E11-K11 | M11: =IF(E11=0,"",L11/E11) | N11: =N10+L11
A12: 46447 | B12: =SUMIFS(收支流水!$E$4:$E$303,收支流水!$B$4:$B$303,"收入",收支流水!$C$4:$C$303,B$5,收支流水!$A$4:$A$303,">="&$A12,收支流水!$A$4:$A$303,"<"&EDATE($A12,1)) | C12: =SUMIFS(收支流水!$E$4:$E$303,收支流水!$B$4:$B$303,"收入",收支流水!$C$4:$C$303,C$5,收支流水!$A$4:$A$303,">="&$A12,收支流水!$A$4:$A$303,"<"&EDATE($A12,1)) | D12: =SUMIFS(收支流水!$E$4:$E$303,收支流水!$B$4:$B$303,"收入",收支流水!$C$4:$C$303,D$5,收支流水!$A$4:$A$303,">="&$A12,收支流水!$A$4:$A$303,"<"&EDATE($A12,1)) | E12: =SUM(B12:D12) | F12: =SUMIFS(收支流水!$E$4:$E$303,收支流水!$B$4:$B$303,"支出",收支流水!$C$4:$C$303,F$5,收支流水!$A$4:$A$303,">="&$A12,收支流水!$A$4:$A$303,"<"&EDATE($A12,1)) | G12: =SUMIFS(收支流水!$E$4:$E$303,收支流水!$B$4:$B$303,"支出",收支流水!$C$4:$C$303,G$5,收支流水!$A$4:$A$303,">="&$A12,收支流水!$A$4:$A$303,"<"&EDATE($A12,1)) | H12: =SUMIFS(收支流水!$E$4:$E$303,收支流水!$B$4:$B$303,"支出",收支流水!$C$4:$C$303,H$5,收支流水!$A$4:$A$303,">="&$A12,收支流水!$A$4:$A$303,"<"&EDATE($A12,1)) | I12: =SUMIFS(收支流水!$E$4:$E$303,收支流水!$B$4:$B$303,"支出",收支流水!$C$4:$C$303,I$5,收支流水!$A$4:$A$303,">="&$A12,收支流水!$A$4:$A$303,"<"&EDATE($A12,1)) | J12: =SUMIFS(收支流水!$E$4:$E$303,收支流水!$B$4:$B$303,"支出",收支流水!$C$4:$C$303,J$5,收支流水!$A$4:$A$303,">="&$A12,收支流水!$A$4:$A$303,"<"&EDATE($A12,1)) | K12: =SUM(F12:J12) | L12: =E12-K12 | M12: =IF(E12=0,"",L12/E12) | N12: =N11+L12
A13: 46478 | B13: =SUMIFS(收支流水!$E$4:$E$303,收支流水!$B$4:$B$303,"收入",收支流水!$C$4:$C$303,B$5,收支流水!$A$4:$A$303,">="&$A13,收支流水!$A$4:$A$303,"<"&EDATE($A13,1)) | C13: =SUMIFS(收支流水!$E$4:$E$303,收支流水!$B$4:$B$303,"收入",收支流水!$C$4:$C$303,C$5,收支流水!$A$4:$A$303,">="&$A13,收支流水!$A$4:$A$303,"<"&EDATE($A13,1)) | D13: =SUMIFS(收支流水!$E$4:$E$303,收支流水!$B$4:$B$303,"收入",收支流水!$C$4:$C$303,D$5,收支流水!$A$4:$A$303,">="&$A13,收支流水!$A$4:$A$303,"<"&EDATE($A13,1)) | E13: =SUM(B13:D13) | F13: =SUMIFS(收支流水!$E$4:$E$303,收支流水!$B$4:$B$303,"支出",收支流水!$C$4:$C$303,F$5,收支流水!$A$4:$A$303,">="&$A13,收支流水!$A$4:$A$303,"<"&EDATE($A13,1)) | G13: =SUMIFS(收支流水!$E$4:$E$303,收支流水!$B$4:$B$303,"支出",收支流水!$C$4:$C$303,G$5,收支流水!$A$4:$A$303,">="&$A13,收支流水!$A$4:$A$303,"<"&EDATE($A13,1)) | H13: =SUMIFS(收支流水!$E$4:$E$303,收支流水!$B$4:$B$303,"支出",收支流水!$C$4:$C$303,H$5,收支流水!$A$4:$A$303,">="&$A13,收支流水!$A$4:$A$303,"<"&EDATE($A13,1)) | I13: =SUMIFS(收支流水!$E$4:$E$303,收支流水!$B$4:$B$303,"支出",收支流水!$C$4:$C$303,I$5,收支流水!$A$4:$A$303,">="&$A13,收支流水!$A$4:$A$303,"<"&EDATE($A13,1)) | J13: =SUMIFS(收支流水!$E$4:$E$303,收支流水!$B$4:$B$303,"支出",收支流水!$C$4:$C$303,J$5,收支流水!$A$4:$A$303,">="&$A13,收支流水!$A$4:$A$303,"<"&EDATE($A13,1)) | K13: =SUM(F13:J13) | L13: =E13-K13 | M13: =IF(E13=0,"",L13/E13) | N13: =N12+L13
A14: 46508 | B14: =SUMIFS(收支流水!$E$4:$E$303,收支流水!$B$4:$B$303,"收入",收支流水!$C$4:$C$303,B$5,收支流水!$A$4:$A$303,">="&$A14,收支流水!$A$4:$A$303,"<"&EDATE($A14,1)) | C14: =SUMIFS(收支流水!$E$4:$E$303,收支流水!$B$4:$B$303,"收入",收支流水!$C$4:$C$303,C$5,收支流水!$A$4:$A$303,">="&$A14,收支流水!$A$4:$A$303,"<"&EDATE($A14,1)) | D14: =SUMIFS(收支流水!$E$4:$E$303,收支流水!$B$4:$B$303,"收入",收支流水!$C$4:$C$303,D$5,收支流水!$A$4:$A$303,">="&$A14,收支流水!$A$4:$A$303,"<"&EDATE($A14,1)) | E14: =SUM(B14:D14) | F14: =SUMIFS(收支流水!$E$4:$E$303,收支流水!$B$4:$B$303,"支出",收支流水!$C$4:$C$303,F$5,收支流水!$A$4:$A$303,">="&$A14,收支流水!$A$4:$A$303,"<"&EDATE($A14,1)) | G14: =SUMIFS(收支流水!$E$4:$E$303,收支流水!$B$4:$B$303,"支出",收支流水!$C$4:$C$303,G$5,收支流水!$A$4:$A$303,">="&$A14,收支流水!$A$4:$A$303,"<"&EDATE($A14,1)) | H14: =SUMIFS(收支流水!$E$4:$E$303,收支流水!$B$4:$B$303,"支出",收支流水!$C$4:$C$303,H$5,收支流水!$A$4:$A$303,">="&$A14,收支流水!$A$4:$A$303,"<"&EDATE($A14,1)) | I14: =SUMIFS(收支流水!$E$4:$E$303,收支流水!$B$4:$B$303,"支出",收支流水!$C$4:$C$303,I$5,收支流水!$A$4:$A$303,">="&$A14,收支流水!$A$4:$A$303,"<"&EDATE($A14,1)) | J14: =SUMIFS(收支流水!$E$4:$E$303,收支流水!$B$4:$B$303,"支出",收支流水!$C$4:$C$303,J$5,收支流水!$A$4:$A$303,">="&$A14,收支流水!$A$4:$A$303,"<"&EDATE($A14,1)) | K14: =SUM(F14:J14) | L14: =E14-K14 | M14: =IF(E14=0,"",L14/E14) | N14: =N13+L14
A15: 46539 | B15: =SUMIFS(收支流水!$E$4:$E$303,收支流水!$B$4:$B$303,"收入",收支流水!$C$4:$C$303,B$5,收支流水!$A$4:$A$303,">="&$A15,收支流水!$A$4:$A$303,"<"&EDATE($A15,1)) | C15: =SUMIFS(收支流水!$E$4:$E$303,收支流水!$B$4:$B$303,"收入",收支流水!$C$4:$C$303,C$5,收支流水!$A$4:$A$303,">="&$A15,收支流水!$A$4:$A$303,"<"&EDATE($A15,1)) | D15: =SUMIFS(收支流水!$E$4:$E$303,收支流水!$B$4:$B$303,"收入",收支流水!$C$4:$C$303,D$5,收支流水!$A$4:$A$303,">="&$A15,收支流水!$A$4:$A$303,"<"&EDATE($A15,1)) | E15: =SUM(B15:D15) | F15: =SUMIFS(收支流水!$E$4:$E$303,收支流水!$B$4:$B$303,"支出",收支流水!$C$4:$C$303,F$5,收支流水!$A$4:$A$303,">="&$A15,收支流水!$A$4:$A$303,"<"&EDATE($A15,1)) | G15: =SUMIFS(收支流水!$E$4:$E$303,收支流水!$B$4:$B$303,"支出",收支流水!$C$4:$C$303,G$5,收支流水!$A$4:$A$303,">="&$A15,收支流水!$A$4:$A$303,"<"&EDATE($A15,1)) | H15: =SUMIFS(收支流水!$E$4:$E$303,收支流水!$B$4:$B$303,"支出",收支流水!$C$4:$C$303,H$5,收支流水!$A$4:$A$303,">="&$A15,收支流水!$A$4:$A$303,"<"&EDATE($A15,1)) | I15: =SUMIFS(收支流水!$E$4:$E$303,收支流水!$B$4:$B$303,"支出",收支流水!$C$4:$C$303,I$5,收支流水!$A$4:$A$303,">="&$A15,收支流水!$A$4:$A$303,"<"&EDATE($A15,1)) | J15: =SUMIFS(收支流水!$E$4:$E$303,收支流水!$B$4:$B$303,"支出",收支流水!$C$4:$C$303,J$5,收支流水!$A$4:$A$303,">="&$A15,收支流水!$A$4:$A$303,"<"&EDATE($A15,1)) | K15: =SUM(F15:J15) | L15: =E15-K15 | M15: =IF(E15=0,"",L15/E15) | N15: =N14+L15
A16: 46569 | B16: =SUMIFS(收支流水!$E$4:$E$303,收支流水!$B$4:$B$303,"收入",收支流水!$C$4:$C$303,B$5,收支流水!$A$4:$A$303,">="&$A16,收支流水!$A$4:$A$303,"<"&EDATE($A16,1)) | C16: =SUMIFS(收支流水!$E$4:$E$303,收支流水!$B$4:$B$303,"收入",收支流水!$C$4:$C$303,C$5,收支流水!$A$4:$A$303,">="&$A16,收支流水!$A$4:$A$303,"<"&EDATE($A16,1)) | D16: =SUMIFS(收支流水!$E$4:$E$303,收支流水!$B$4:$B$303,"收入",收支流水!$C$4:$C$303,D$5,收支流水!$A$4:$A$303,">="&$A16,收支流水!$A$4:$A$303,"<"&EDATE($A16,1)) | E16: =SUM(B16:D16) | F16: =SUMIFS(收支流水!$E$4:$E$303,收支流水!$B$4:$B$303,"支出",收支流水!$C$4:$C$303,F$5,收支流水!$A$4:$A$303,">="&$A16,收支流水!$A$4:$A$303,"<"&EDATE($A16,1)) | G16: =SUMIFS(收支流水!$E$4:$E$303,收支流水!$B$4:$B$303,"支出",收支流水!$C$4:$C$303,G$5,收支流水!$A$4:$A$303,">="&$A16,收支流水!$A$4:$A$303,"<"&EDATE($A16,1)) | H16: =SUMIFS(收支流水!$E$4:$E$303,收支流水!$B$4:$B$303,"支出",收支流水!$C$4:$C$303,H$5,收支流水!$A$4:$A$303,">="&$A16,收支流水!$A$4:$A$303,"<"&EDATE($A16,1)) | I16: =SUMIFS(收支流水!$E$4:$E$303,收支流水!$B$4:$B$303,"支出",收支流水!$C$4:$C$303,I$5,收支流水!$A$4:$A$303,">="&$A16,收支流水!$A$4:$A$303,"<"&EDATE($A16,1)) | J16: =SUMIFS(收支流水!$E$4:$E$303,收支流水!$B$4:$B$303,"支出",收支流水!$C$4:$C$303,J$5,收支流水!$A$4:$A$303,">="&$A16,收支流水!$A$4:$A$303,"<"&EDATE($A16,1)) | K16: =SUM(F16:J16) | L16: =E16-K16 | M16: =IF(E16=0,"",L16/E16) | N16: =N15+L16
A17: 46600 | B17: =SUMIFS(收支流水!$E$4:$E$303,收支流水!$B$4:$B$303,"收入",收支流水!$C$4:$C$303,B$5,收支流水!$A$4:$A$303,">="&$A17,收支流水!$A$4:$A$303,"<"&EDATE($A17,1)) | C17: =SUMIFS(收支流水!$E$4:$E$303,收支流水!$B$4:$B$303,"收入",收支流水!$C$4:$C$303,C$5,收支流水!$A$4:$A$303,">="&$A17,收支流水!$A$4:$A$303,"<"&EDATE($A17,1)) | D17: =SUMIFS(收支流水!$E$4:$E$303,收支流水!$B$4:$B$303,"收入",收支流水!$C$4:$C$303,D$5,收支流水!$A$4:$A$303,">="&$A17,收支流水!$A$4:$A$303,"<"&EDATE($A17,1)) | E17: =SUM(B17:D17) | F17: =SUMIFS(收支流水!$E$4:$E$303,收支流水!$B$4:$B$303,"支出",收支流水!$C$4:$C$303,F$5,收支流水!$A$4:$A$303,">="&$A17,收支流水!$A$4:$A$303,"<"&EDATE($A17,1)) | G17: =SUMIFS(收支流水!$E$4:$E$303,收支流水!$B$4:$B$303,"支出",收支流水!$C$4:$C$303,G$5,收支流水!$A$4:$A$303,">="&$A17,收支流水!$A$4:$A$303,"<"&EDATE($A17,1)) | H17: =SUMIFS(收支流水!$E$4:$E$303,收支流水!$B$4:$B$303,"支出",收支流水!$C$4:$C$303,H$5,收支流水!$A$4:$A$303,">="&$A17,收支流水!$A$4:$A$303,"<"&EDATE($A17,1)) | I17: =SUMIFS(收支流水!$E$4:$E$303,收支流水!$B$4:$B$303,"支出",收支流水!$C$4:$C$303,I$5,收支流水!$A$4:$A$303,">="&$A17,收支流水!$A$4:$A$303,"<"&EDATE($A17,1)) | J17: =SUMIFS(收支流水!$E$4:$E$303,收支流水!$B$4:$B$303,"支出",收支流水!$C$4:$C$303,J$5,收支流水!$A$4:$A$303,">="&$A17,收支流水!$A$4:$A$303,"<"&EDATE($A17,1)) | K17: =SUM(F17:J17) | L17: =E17-K17 | M17: =IF(E17=0,"",L17/E17) | N17: =N16+L17
A18: 46631 | B18: =SUMIFS(收支流水!$E$4:$E$303,收支流水!$B$4:$B$303,"收入",收支流水!$C$4:$C$303,B$5,收支流水!$A$4:$A$303,">="&$A18,收支流水!$A$4:$A$303,"<"&EDATE($A18,1)) | C18: =SUMIFS(收支流水!$E$4:$E$303,收支流水!$B$4:$B$303,"收入",收支流水!$C$4:$C$303,C$5,收支流水!$A$4:$A$303,">="&$A18,收支流水!$A$4:$A$303,"<"&EDATE($A18,1)) | D18: =SUMIFS(收支流水!$E$4:$E$303,收支流水!$B$4:$B$303,"收入",收支流水!$C$4:$C$303,D$5,收支流水!$A$4:$A$303,">="&$A18,收支流水!$A$4:$A$303,"<"&EDATE($A18,1)) | E18: =SUM(B18:D18) | F18: =SUMIFS(收支流水!$E$4:$E$303,收支流水!$B$4:$B$303,"支出",收支流水!$C$4:$C$303,F$5,收支流水!$A$4:$A$303,">="&$A18,收支流水!$A$4:$A$303,"<"&EDATE($A18,1)) | G18: =SUMIFS(收支流水!$E$4:$E$303,收支流水!$B$4:$B$303,"支出",收支流水!$C$4:$C$303,G$5,收支流水!$A$4:$A$303,">="&$A18,收支流水!$A$4:$A$303,"<"&EDATE($A18,1)) | H18: =SUMIFS(收支流水!$E$4:$E$303,收支流水!$B$4:$B$303,"支出",收支流水!$C$4:$C$303,H$5,收支流水!$A$4:$A$303,">="&$A18,收支流水!$A$4:$A$303,"<"&EDATE($A18,1)) | I18: =SUMIFS(收支流水!$E$4:$E$303,收支流水!$B$4:$B$303,"支出",收支流水!$C$4:$C$303,I$5,收支流水!$A$4:$A$303,">="&$A18,收支流水!$A$4:$A$303,"<"&EDATE($A18,1)) | J18: =SUMIFS(收支流水!$E$4:$E$303,收支流水!$B$4:$B$303,"支出",收支流水!$C$4:$C$303,J$5,收支流水!$A$4:$A$303,">="&$A18,收支流水!$A$4:$A$303,"<"&EDATE($A18,1)) | K18: =SUM(F18:J18) | L18: =E18-K18 | M18: =IF(E18=0,"",L18/E18) | N18: =N17+L18
... A29: 46966 | B29: =SUMIFS(收支流水!$E$4:$E$303,收支流水!$B$4:$B$303,"收入",收支流水!$C$4:$C$303,B$5,收支流水!$A$4:$A$303,">="&$A29,收支流水!$A$4:$A$303,"<"&EDATE($A29,1)) | C29: =SUMIFS(收支流水!$E$4:$E$303,收支流水!$B$4:$B$303,"收入",收支流水!$C$4:$C$303,C$5,收支流水!$A$4:$A$303,">="&$A29,收支流水!$A$4:$A$303,"<"&EDATE($A29,1)) | D29: =SUMIFS(收支流水!$E$4:$E$303,收支流水!$B$4:$B$303,"收入",收支流水!$C$4:$C$303,D$5,收支流水!$A$4:$A$303,">="&$A29,收支流水!$A$4:$A$303,"<"&EDATE($A29,1)) | E29: =SUM(B29:D29) | F29: =SUMIFS(收支流水!$E$4:$E$303,收支流水!$B$4:$B$303,"支出",收支流水!$C$4:$C$303,F$5,收支流水!$A$4:$A$303,">="&$A29,收支流水!$A$4:$A$303,"<"&EDATE($A29,1)) | G29: =SUMIFS(收支流水!$E$4:$E$303,收支流水!$B$4:$B$303,"支出",收支流水!$C$4:$C$303,G$5,收支流水!$A$4:$A$303,">="&$A29,收支流水!$A$4:$A$303,"<"&EDATE($A29,1)) | H29: =SUMIFS(收支流水!$E$4:$E$303,收支流水!$B$4:$B$303,"支出",收支流水!$C$4:$C$303,H$5,收支流水!$A$4:$A$303,">="&$A29,收支流水!$A$4:$A$303,"<"&EDATE($A29,1)) | I29: =SUMIFS(收支流水!$E$4:$E$303,收支流水!$B$4:$B$303,"支出",收支流水!$C$4:$C$303,I$5,收支流水!$A$4:$A$303,">="&$A29,收支流水!$A$4:$A$303,"<"&EDATE($A29,1)) | J29: =SUMIFS(收支流水!$E$4:$E$303,收支流水!$B$4:$B$303,"支出",收支流水!$C$4:$C$303,J$5,收支流水!$A$4:$A$303,">="&$A29,收支流水!$A$4:$A$303,"<"&EDATE($A29,1)) | K29: =SUM(F29:J29) | L29: =E29-K29 | M29: =IF(E29=0,"",L29/E29) | N29: =N28+L29
A31: 二、年度汇总
A32: 年度 | B32: 收入合计 | C32: 支出合计 | D32: 年结余 | E32: 储蓄率
A33: 2026 | B33: =SUM(E6:E9) | C33: =SUM(K6:K9) | D33: =B33-C33 | E33: =IF(B33=0,"",D33/B33)
A34: 2027 | B34: =SUM(E10:E21) | C34: =SUM(K10:K21) | D34: =B34-C34 | E34: =IF(B34=0,"",D34/B34)
A35: 2028 | B35: =SUM(E22:E29) | C35: =SUM(K22:K29) | D35: =B35-C35 | E35: =IF(B35=0,"",D35/B35)
A37: 三、滚动统计（供 FIRE 测算自动取值）
A38: 有记录月份数(月) | B38: =COUNTIF(K6:K29,">0")
A39: 月均支出(元) | B39: =IF(B38=0,0,SUM(K6:K29)/B38)
A40: 年化支出(元) | B40: =B39*12
A41: 月均收入(元) | B41: =IF(B38=0,0,SUM(E6:E29)/B38)
A42: 年化收入(元) | B42: =B41*12
A43: 年化储蓄(元) | B43: =B42-B40
A44: 储蓄率 | B44: =IF(B42=0,"",B43/B42)

Sheet 收支流水
A1: 收支流水登记表
A2: 在下方逐笔登记；「类型」「类别」请使用下拉选择，填好后上方「收支记账」会自动汇总
A3: 日期 | B3: 类型 | C3: 类别 | D3: 项目说明 | E3: 金额(元) | F3: 备注

Sheet 月度净值跟踪
A1: 月度净资产跟踪表
A2: 每月月末更新一次即可；2026-09 行已自动链接「资产明细」，后续月份请手工填写各分类金额；房产 1,315 万（自用 1,000 万＋投资性房地产 315 万）已纳入资产明细与总览看板，本表未单列房产
A3: 月份 | B3: 现金及存款 | C3: 股票及证券 | D3: 基金及理财 | E3: 保险(储蓄型) | F3: 总资产 | G3: 总负债 | H3: 净资产 | I3: 环比增减 | J3: 环比% | K3: FIRE进度 | L3: 教育金专项(备查) | M3: 备注
A4: 46266 | B4: =资产明细!G8 | C4: =资产明细!G15 | D4: =资产明细!G19 | E4: =资产明细!G24 | F4: =IF(COUNT(B4:E4)=0,"",SUM(B4:E4)) | G4: =资产明细!G40 | H4: =IF(F4="","",F4-N(G4)) | K4: =IF(F4="","",IFERROR((N(B4)+N(C4)+N(D4))/FIRE目标,"")) | L4: =资产明细!G27 | M4: 2026-09 快照。口径提示：本表「总资产」＝现金＋股票＋基金＋储蓄型保险（不含教育金与房产），但「总负债」含房贷 200 万（该负债对应自住房产，房产与投资房均未计入本表资产），因此本表净资产比全表口径（2,387.6 万）偏低约 800 万，仅供跟踪可投资资产的净值变化趋势。中信账户已拆分：阿里港股通 6,400 股、九毛九 63,000 股单列，账户按净额计。
A5: 46296 | F5: =IF(COUNT(B5:E5)=0,"",SUM(B5:E5)) | H5: =IF(F5="","",F5-N(G5)) | I5: =IF(OR(F5="",F4=""),"",H5-H4) | J5: =IF(OR(I5="",H4=0,H4=""),"",I5/H4) | K5: =IF(F5="","",IFERROR((N(B5)+N(C5)+N(D5))/FIRE目标,""))
A6: 46327 | F6: =IF(COUNT(B6:E6)=0,"",SUM(B6:E6)) | H6: =IF(F6="","",F6-N(G6)) | I6: =IF(OR(F6="",F5=""),"",H6-H5) | J6: =IF(OR(I6="",H5=0,H5=""),"",I6/H5) | K6: =IF(F6="","",IFERROR((N(B6)+N(C6)+N(D6))/FIRE目标,""))
A7: 46357 | F7: =IF(COUNT(B7:E7)=0,"",SUM(B7:E7)) | H7: =IF(F7="","",F7-N(G7)) | I7: =IF(OR(F7="",F6=""),"",H7-H6) | J7: =IF(OR(I7="",H6=0,H6=""),"",I7/H6) | K7: =IF(F7="","",IFERROR((N(B7)+N(C7)+N(D7))/FIRE目标,""))
A8: 46388 | F8: =IF(COUNT(B8:E8)=0,"",SUM(B8:E8)) | H8: =IF(F8="","",F8-N(G8)) | I8: =IF(OR(F8="",F7=""),"",H8-H7) | J8: =IF(OR(I8="",H7=0,H7=""),"",I8/H7) | K8: =IF(F8="","",IFERROR((N(B8)+N(C8)+N(D8))/FIRE目标,""))
A9: 46419 | F9: =IF(COUNT(B9:E9)=0,"",SUM(B9:E9)) | H9: =IF(F9="","",F9-N(G9)) | I9: =IF(OR(F9="",F8=""),"",H9-H8) | J9: =IF(OR(I9="",H8=0,H8=""),"",I9/H8) | K9: =IF(F9="","",IFERROR((N(B9)+N(C9)+N(D9))/FIRE目标,""))
A10: 46447 | F10: =IF(COUNT(B10:E10)=0,"",SUM(B10:E10)) | H10: =IF(F10="","",F10-N(G10)) | I10: =IF(OR(F10="",F9=""),"",H10-H9) | J10: =IF(OR(I10="",H9=0,H9=""),"",I10/H9) | K10: =IF(F10="","",IFERROR((N(B10)+N(C10)+N(D10))/FIRE目标,""))
A11: 46478 | F11: =IF(COUNT(B11:E11)=0,"",SUM(B11:E11)) | H11: =IF(F11="","",F11-N(G11)) | I11: =IF(OR(F11="",F10=""),"",H11-H10) | J11: =IF(OR(I11="",H10=0,H10=""),"",I11/H10) | K11: =IF(F11="","",IFERROR((N(B11)+N(C11)+N(D11))/FIRE目标,""))
A12: 46508 | F12: =IF(COUNT(B12:E12)=0,"",SUM(B12:E12)) | H12: =IF(F12="","",F12-N(G12)) | I12: =IF(OR(F12="",F11=""),"",H12-H11) | J12: =IF(OR(I12="",H11=0,H11=""),"",I12/H11) | K12: =IF(F12="","",IFERROR((N(B12)+N(C12)+N(D12))/FIRE目标,""))
A13: 46539 | F13: =IF(COUNT(B13:E13)=0,"",SUM(B13:E13)) | H13: =IF(F13="","",F13-N(G13)) | I13: =IF(OR(F13="",F12=""),"",H13-H12) | J13: =IF(OR(I13="",H12=0,H12=""),"",I13/H12) | K13: =IF(F13="","",IFERROR((N(B13)+N(C13)+N(D13))/FIRE目标,""))
A14: 46569 | F14: =IF(COUNT(B14:E14)=0,"",SUM(B14:E14)) | H14: =IF(F14="","",F14-N(G14)) | I14: =IF(OR(F14="",F13=""),"",H14-H13) | J14: =IF(OR(I14="",H13=0,H13=""),"",I14/H13) | K14: =IF(F14="","",IFERROR((N(B14)+N(C14)+N(D14))/FIRE目标,""))
A15: 46600 | F15: =IF(COUNT(B15:E15)=0,"",SUM(B15:E15)) | H15: =IF(F15="","",F15-N(G15)) | I15: =IF(OR(F15="",F14=""),"",H15-H14) | J15: =IF(OR(I15="",H14=0,H14=""),"",I15/H14) | K15: =IF(F15="","",IFERROR((N(B15)+N(C15)+N(D15))/FIRE目标,""))
A16: 46631 | F16: =IF(COUNT(B16:E16)=0,"",SUM(B16:E16)) | H16: =IF(F16="","",F16-N(G16)) | I16: =IF(OR(F16="",F15=""),"",H16-H15) | J16: =IF(OR(I16="",H15=0,H15=""),"",I16/H15) | K16: =IF(F16="","",IFERROR((N(B16)+N(C16)+N(D16))/FIRE目标,""))
... A27: 46966 | F27: =IF(COUNT(B27:E27)=0,"",SUM(B27:E27)) | H27: =IF(F27="","",F27-N(G27)) | I27: =IF(OR(F27="",F26=""),"",H27-H26) | J27: =IF(OR(I27="",H26=0,H26=""),"",I27/H26) | K27: =IF(F27="","",IFERROR((N(B27)+N(C27)+N(D27))/FIRE目标,""))
A29: 说明 | B29: 「FIRE进度」＝(现金＋股票＋基金)÷ FIRE目标。FIRE目标 为定义名称，指向「FIRE测算」的目标资产单元格，因此新增/删除参数行不会导致引用错位。教育金专项（恒泰尊享现价）单列备查，不计入 FIRE 进度。

Sheet FIRE测算
A1: FIRE 财务自由测算
A2: FIRE＝Financial Independence, Retire Early；以「年支出÷安全提款率」为目标资产，动态判断达成时间
A3: 一、核心参数与假设
A4: 参数 | B4: 数值 | C4: 单位 | D4: 说明
A5: 当前年龄 | B5: 46 | C5: 岁 | D5: 手工输入（黄色＝重点假设）
A6: 安全提款率 SWR | B6: 0.04 | C6: % | D6: 4% 法则：年支出÷4%＝所需资产（25倍年支出）
A7: 预期投资年化收益率（名义） | B7: 0.07 | C7: % | D7: 股/基/现金组合的长期期望收益，请按自身风险偏好调整
A8: 预期通胀率 | B8: 0.025 | C8: % | D8: 用于换算实际收益率
A9: 手动年支出估算（元） | B9: 500000 | C9: 元 | D9: 无记账数据时采用此值
A10: 手动年储蓄估算（元） | B10: 400000 | C10: 元 | D10: 无记账数据时采用此值
A11: 是否计入保险年金现价 | B11: 否 | C11: 是/否 | D11: ★推荐「否」：泰康年金现价在 60 岁后递减、84 岁归零，其价值已由「三、两阶段目标」以收入流方式处理；计入会重复计算
A12: 年支出（记账表自动） | B12: =收支记账!B40 | C12: 元 | D12: ＝记账表「年化支出」
A13: 年储蓄（记账表自动） | B13: =收支记账!B43 | C13: 元 | D13: ＝记账表「年化储蓄」
A14: 采用年支出（元） | B14: =IF(B12>0,B12,B9) | C14: 元 | D14: 有记账数据则优先用记账数据，否则用手动估算
A15: 采用年储蓄（元） | B15: =IF(B13>0,B13,B10) | C15: 元 | D15: 同上
A16: 年金起始领取年龄 | B16: 60 | C16: 岁 | D16: 泰康乐享百岁：60 岁起按月领取（条款 1.4）
A17: 年金月领取额（元） | B17: 15000 | C17: 元 | D17: 取自保单：基本保险金额 = 15,000 元/月
A18: 年金年领取额（元） | B18: =B17*11.866 | C18: 元 | D18: ＝月领取额 × 11.866（条款 1.4 的换算系数）
A19: 退休后是否停止储蓄 | B19: 是 | C19: 是/否 | D19: 退休后不再有工资性储蓄，推演按此切换
A20: 二、FIRE 目标与当前进度
A21: FIRE 目标资产（元） | B21: =IF(B6=0,"",B14/B6) | D21: ＝采用年支出 ÷ SWR（不含年金的稳健口径）
A22: 现金及存款（元） | B22: =资产明细!G8 | D22: 链接「资产明细」
A23: 股票及证券（元） | B23: =资产明细!G15
A24: 基金及理财（元） | B24: =资产明细!G19
A25: 保险(储蓄型)现价（元） | B25: =资产明细!G24 | D25: 泰康年金 ＋ 中意增额寿 ＋ 金管家万能
A26: 可投资资产合计（元） | B26: =IF(B11="是",B22+B23+B24+B25,B22+B23+B24) | D26: 按「是否计入保险年金现价」开关计算
A27: 教育金专项（元，不计入） | B27: =资产明细!G27 | D27: ★恒泰尊享现价已指定用于女儿大学四年，不参与 FIRE
A28: FIRE 进度 | B28: =IFERROR(B26/B21,"") | D28: ＝可投资资产 ÷ FIRE目标
A29: 财务自由度（现金流入覆盖率） | B29: =IFERROR((B26*B6+B18)/B14,"") | D29: ＝(可投资资产×SWR ＋ 年金年领取额) ÷ 年支出；≥100% 即达成
A30: FIRE 缺口（元） | B30: =MAX(B21-B26,0) | D30: ＝MAX(FIRE目标－可投资资产, 0)
A31: FIRE 状态 | B31: =IF(B14=0,"待填写年支出",IF(B29>=1,"已达成财务自由",IF(B29>=0.7,"接近达成（现金流入覆盖70%以上）","积累中"))) | D31: 自动判定
A33: 三、含年金的两阶段目标（修正口径：年金作为收入流，不重复计入资产）
A34: 阶段1：46 → 59 岁支出现值（元） | B34: =IFERROR(B14*(1-(1+((1+B7)/(1+B8)-1))^-($B$16-$B$5))/(((1+B7)/(1+B8)-1)),"") | D34: 无年金期间，年支出全部由资产承担
A35: 阶段2：60 岁起年净支出（元） | B35: =MAX(B14-B18,0) | D35: ＝年支出 － 年金年领取额
A36: 阶段2所需资产（60 岁，元） | B36: =IF(B6=0,"",B35/B6) | D36: ＝阶段2净支出 ÷ SWR
A37: 阶段2现值（折现至 46 岁，元） | B37: =IFERROR(B36/(1+((1+B7)/(1+B8)-1))^($B$16-$B$5),"") | D37: 按实际收益率折现
A38: 含年金的所需资产合计（元） | B38: =IFERROR(B34+B37,"") | D38: ★纳入年金后的真实目标，通常显著低于 750 万
A39: 年金的资产释放效应（元） | B39: =B21-B38 | D39: ＝不含年金目标 － 含年金所需资产
A40: 对照：含年金口径的充裕度 | B40: =IFERROR(B26/B38,"") | D40: ＝可投资资产 ÷ 含年金所需资产
A41: 四、达成时间测算
...

Sheet 使用说明
A1: 使用说明与口径定义
A2: 版本：2026-09 生成
A3: 一、工作表说明
B4: 总览看板 | C4: 自动汇总的驾驶舱：资产总览、FIRE 进度、达成时间、投资收益概览。无需手工修改。
B5: 资产明细 | C5: 所有非房产资产的分类台账。保险按【现金价值】口径分「储蓄型」「教育金专项」两组。蓝色字体为手工输入项。
B6: 保险权益与现金流 | C6: 4 张保单台账、按年龄的现金价值与年金现金流、保障缺口分析、IRR 测算、保单可用资金工具对比。
B7: 教育金规划 | C7: 以「恒泰尊享 3.0」现价为来源，按条款 11.2 的 20%/年 减保上限，逐年推演女儿 18–22 岁大学四年可取现金额。
B8: 收支记账 | C8: 月度/年度收支汇总，自动从小表「收支流水」汇总，无需手工填写数字。
B9: 收支流水 | C9: 逐笔登记收支的流水表。只需填写「日期／类型／类别／金额」四列。
B10: 月度净值跟踪 | C10: 每月月末登记一次各类资产金额，观察净资产曲线与 FIRE 进度变化；教育金专项单列备查。
B11: FIRE测算 | C11: FIRE 参数、目标、进度、达成时间、分级评估，含年金的两阶段目标，以及 46→99 岁逐年推演。
A12: 二、维护频率（建议）
B13: 每月一次 | C13: ① 收支流水补录当月收支；② 月度净值跟踪填写当月各分类金额。
B14: 每季度一次 | C14: 资产明细中更新股价、汇率、银行余额、基金净值。
B15: 每半年一次 | C15: 复核 FIRE 参数：年支出、年储蓄、预期收益率、安全提款率。
A16: 三、FIRE 计算逻辑
B17: FIRE 目标资产 | C17: ＝ 采用年支出 ÷ 安全提款率(SWR)。默认 SWR＝4%，即 25 倍年支出（4% 法则）。
B18: 可投资资产 | C18: ＝ 现金及存款 ＋ 股票及证券 ＋ 基金及理财（默认不含保险；教育金专项永不参与）。年金是否计入由「是否计入保险年金现价」开关控制。
B19: 财务自由度 | C19: ＝(可投资资产 × SWR ＋ 年金年领取额) ÷ 年支出。达 100% 即「现金流入口径」可覆盖全部支出。
B20: 达成时间 | C20: ＝ NPER(实际收益率, －年储蓄, －当前可投资资产, FIRE目标)。实际收益率＝(1+名义收益率)÷(1+通胀率)－1。
B21: 分级评估 | C21: 极简 FIRE＝年支出×20（SWR 5%）；标准 FIRE＝×25（SWR 4%）；充裕 FIRE＝×33.3（SWR 3%）；并给出「含年金」口径的所需资产。
B22: 两阶段目标 | C22: ★年金是合同确定的现金流，性质等同债券，按年 177,990 元、自 60 岁起，用实际收益率折现，而非用 SWR 资本化。资产口径与现金流入口径须分开看。
A23: 四、年支出／年储蓄的取值口径
B24: 优先 | C24: 取自「收支记账」的滚动统计：按有记录的月份数取月均，再乘 12 折算为年化值。
B25: 兜底 | C25: 若「收支流水」尚无数据，则采用 FIRE测算 中的「手动年支出估算／手动年储蓄估算」（默认 30万／40万，请按实际修改）。
A26: 五、本次建表的数据口径与假设（请核对）
B27: 现金 | C27: 招商银行 131 万、工商银行 24.3 万，合计 155.3 万。
B28: 阿里巴巴持股 | C28: 港股通 6,400 股（含在中信证券账户内）＋ H股 4,004 股（3164＋840）＋ 美股 ADR 2,177 股。汇率默认 HKD 0.92、USD 7.15。
B29: 阿里股价 | C29: 已按 2026-09-15 市价更新：港股 107.20 HKD／美股 109.51 USD（请按最新价维护，勿再用占位值）。
B30: 阿里成本 | C30: 港股通 6,400 股成本 147 HKD；九毛九成本 11.68 HKD；RSU 来源（H股 4,004 股＋美股 2,177 股）系公司授予，无自购成本，暂不计盈亏。
B31: 中信证券账户 | C31: ★中信账户 322 万市值内含阿里港股通 6,400 股与九毛九 63,000 股，二者已在资产明细单列，账户按净额列示（避免重复计算）。
B32: 高毅晓峰基金 | C32: 本金 100 万，2021-06 买入，当前市值 151 万（浮盈 51 万）。
B33: 泰康赢家人生 | C33: 投连险，本金 80 万，2020-12 买入，当前市值 84.4 万（浮盈 4.4 万）。
B34: 保险估值口径 | C34: ★全部保险统一按【保单现金价值】计入，不再按累计已交保费口径（旧版口径会高估资产、掩盖退保损失）。
B35: 泰康乐享百岁 | C35: 养老年金，累计保费 301.25 万，现价 186.25 万（60 岁前）；60 岁起月领 1.5 万／年领 17.799 万，保证给付 25 年，60 岁后身故金为 0，现价至 84 岁归零。
B36: 中意一生中意 | C36: 增额终身寿（分红），累计保费 4 万，现价 3.56 万；★受益人为「法定受益人」，建议改为指定受益人。
B37: 陆家嘴国泰恒泰尊享3.0 | C37: ★教育金专项：累计保费 200 万，现价 160.06 万；用于女儿 18–22 岁大学四年，不参与 FIRE，单列看板。
B38: 陆家嘴国泰金管家2.0 | C38: 万能险，趸交 1,000 元，现价 1,000 元；金额极小，仅作账户载体。
... B40: 负债 | C40: 负债：深圳城市山林抵押贷款余额约 200 万，已填入「资产明细」负债区；请按实际剩余贷款额定期更新。
A41: 六、注意事项
...
